测试函数
# 导入unittest
import unittest
导入想要测试的函数
from name_function import get_formatted_name
#继承unitest类
class NameTestCase（unittest.Testcase):
  #定义方法
  def test——first——last——name（self）：
    formatted——name = get_formatted_name（‘形参一’，‘形参2’）
    运用断言函数判断程序能否正常处理
    self.arrestEqual（formatted_name,'形参一，形参2）
unitest.main()
出现问题：
Testing started at 8:57 ...
F:\deep\venv\Scripts\python.exe "F:\pycharm\PyCharm 2019.2\helpers\pycharm\_jb_unittest_runner.py" --path F:/deep/1est_name_function.py
Launching unittests with arguments python -m unittest F:/deep/1est_name_function.py in F:\deep


----------------------------------------------------------------------
Ran 0 tests in 0.000s

OK

Process finished with exit code 0

Empty suite
找到两种解决办法 但是一直没有解决
！！！ 解决办法 对于测试函数以test开头 结果
Testing started at 10:21 ...
F:\deep\venv\Scripts\python.exe "F:\pycharm\PyCharm 2019.2\helpers\pycharm\_jb_unittest_runner.py" --path F:/deep/1est_name_function.py
Launching unittests with arguments python -m unittest F:/deep/1est_name_function.py in F:\deep



Ran 1 test in 0.002s

OK

Process finished with exit code 0


测试类


各种断言方法
arrestEqual(a,b) 核实a=b
arrestnotEqual（a，b）a！=b
arrestTrue（X） 核实为真
arrestFalse（X）核实为假
arrestinIn（item list）核实item在list中
arrestnotIn（item list）核实item不在list中
